<?xml version="1.0" encoding="utf-8"?>
<!-- =================================================================================== -->
<!-- |    This document was autogenerated by xacro from aidboat_aft_thrusters.xacro    | -->
<!-- |    EDITING THIS FILE BY HAND IS NOT RECOMMENDED                                 | -->
<!-- =================================================================================== -->
<robot>
  <!--<gazebo>
    <plugin name="aidboat_gazebo_thrust" filename="libusv_gazebo_thrust_plugin.so" xmlns:xacro="http://ros.org/wiki/xacro">
      <cmdTimeout>1.0</cmdTimeout>
      <thruster>
        <linkName>left_propeller_link</linkName>
        <propJointName>left_engine_propeller_joint</propJointName>
        <engineJointName>left_chasis_engine_joint</engineJointName>
        <cmdTopic>left_thrust_cmd</cmdTopic>
        <angleTopic>left_thrust_angle</angleTopic>
        <enableAngle>false</enableAngle>
      </thruster>
      <thruster>
        <linkName>right_propeller_link</linkName>
        <propJointName>right_engine_propeller_joint</propJointName>
        <engineJointName>right_chasis_engine_joint</engineJointName>
        <cmdTopic>right_thrust_cmd</cmdTopic>
        <angleTopic>right_thrust_angle</angleTopic>
        <enableAngle>false</enableAngle>
      </thruster>
    </plugin>
  </gazebo>-->
  <link name="right_engine_link">
    <visual>
      <origin rpy="0 0 0.0244346" xyz="0 0 0"/>
      <geometry>
        <mesh filename="package://aidboat_description/models/engine/mesh/right_engine.dae"/>
      </geometry>
    </visual>
    <collision>
      <origin rpy="0 1.5708 0.0244346" xyz="0.011 0 0"/>
      <geometry>
        <cylinder length="0.113" radius="0.05"/>
      </geometry>
    </collision>
    <inertial>
      <mass value="0.126"/>
      <inertia ixx="0.00002900992" ixy="0" ixz="0" iyy="0.00002900992" iyz="0" izz="0.0001575"/>
    </inertial>
  </link>
  <link name="right_propeller_link">
    <visual>
      <origin rpy="0 0 0.0244346" xyz="0 0 0"/>
      <geometry>
        <mesh filename="package://aidboat_description/models/propeller/mesh/right_propeller.dae"/>
      </geometry>
    </visual>
    <collision>
      <origin rpy="0 1.5708 0.0244346" xyz="0.011 0 0"/>
      <geometry>
        <cylinder length="0.03" radius="0.0381"/>
      </geometry>
    </collision>
    <inertial>
      <mass value="0.030"/>
      <inertia ixx="0.00000058378" ixy="0" ixz="0" iyy="0.00000058378" iyz="0" izz="0.00002177415"/>
    </inertial>
  </link>
  <joint name="right_chasis_engine_joint" type="fixed">
    <origin rpy="0 0 0" xyz="-0.741 -0.47 -0.016"/>
    <parent link="base_link"/>
    <child link="right_engine_link"/>
  </joint>
  <joint name="right_engine_propeller_joint" type="continuous">
    <axis rpy="0 0 0" xyz="1 0 0"/>
    <parent link="right_engine_link"/>
    <child link="right_propeller_link"/>
    <origin rpy="0 0 0" xyz="0 0 0"/>
    <limit effort="0.7250" velocity="369.97489"/>
    <dynamics damping="0.05" friction="0.05"/>
  </joint>
  <gazebo reference="right_engine_link">
    <mu1>0.2</mu1>
    <mu2>0.2</mu2>
  </gazebo>
  <gazebo reference="right_propeller_link">
    <mu1>0.2</mu1>
    <mu2>0.2</mu2>
  </gazebo>
  <link name="left_engine_link">
    <visual>
      <origin rpy="0 0 -0.0244346" xyz="0 0 0"/>
      <geometry>
        <mesh filename="package://aidboat_description/models/engine/mesh/left_engine.dae"/>
      </geometry>
    </visual>
    <collision>
      <origin rpy="0 1.5708 -0.0244346" xyz="0.011 0 0"/>
      <geometry>
        <cylinder length="0.113" radius="0.05"/>
      </geometry>
    </collision>
    <inertial>
      <mass value="0.126"/>
      <inertia ixx="0.00002900992" ixy="0" ixz="0" iyy="0.00002900992" iyz="0" izz="0.0001575"/>
    </inertial>
  </link>
  <link name="left_propeller_link">
    <visual>
      <origin rpy="0 0 -0.0244346" xyz="0 0 0"/>
      <geometry>
        <mesh filename="package://aidboat_description/models/propeller/mesh/left_propeller.dae"/>
      </geometry>
    </visual>
    <collision>
      <origin rpy="0 1.5708 -0.0244346" xyz="0.011 0 0"/>
      <geometry>
        <cylinder length="0.03" radius="0.0381"/>
      </geometry>
    </collision>
    <inertial>
      <mass value="0.030"/>
      <inertia ixx="0.00000058378" ixy="0" ixz="0" iyy="0.00000058378" iyz="0" izz="0.00002177415"/>
    </inertial>
  </link>
  <joint name="left_chasis_engine_joint" type="fixed">
    <origin rpy="0 0 0" xyz="-0.741 0.47 -0.016"/>
    <parent link="base_link"/>
    <child link="left_engine_link"/>
  </joint>
  <joint name="left_engine_propeller_joint" type="continuous">
    <axis rpy="0 0 0" xyz="1 0 0"/>
    <parent link="left_engine_link"/>
    <child link="left_propeller_link"/>
    <origin rpy="0 0 0" xyz="0 0 0"/>
    <limit effort="0.7250" velocity="369.97489"/>
    <dynamics damping="0.05" friction="0.05"/>
  </joint>
  <gazebo reference="left_engine_link">
    <mu1>0.2</mu1>
    <mu2>0.2</mu2>
  </gazebo>
  <gazebo reference="left_propeller_link">
    <mu1>0.2</mu1>
    <mu2>0.2</mu2>
  </gazebo>
  <gazebo>
    <plugin filename="libusv_gazebo_thrust_plugin.so" name="aidboat_gazebo_thrust">
      <cmdTimeout>1.0</cmdTimeout>
      <robotNamespace>aidboat</robotNamespace>
      <thruster>
        <!-- Required Parameters -->
        <linkName>left_propeller_link</linkName>
        <propJointName>left_engine_propeller_joint</propJointName>
        <engineJointName>left_chasis_engine_joint</engineJointName>
        <cmdTopic>left_thrust_cmd</cmdTopic>
        <angleTopic>left_thrust_angle</angleTopic>
        <enableAngle>False</enableAngle>
        <!-- Optional Parameters -->
        <mappingType>1</mappingType>
        <maxCmd>1.0</maxCmd>
        <maxForceFwd>250.0</maxForceFwd>
        <maxForceRev>-100.0</maxForceRev>
        <maxAngle>1.57079632679</maxAngle>
      </thruster>
      <thruster>
        <!-- Required Parameters -->
        <linkName>right_propeller_link</linkName>
        <propJointName>right_engine_propeller_joint</propJointName>
        <engineJointName>right_chasis_engine_joint</engineJointName>
        <cmdTopic>right_thrust_cmd</cmdTopic>
        <angleTopic>right_thrust_angle</angleTopic>
        <enableAngle>False</enableAngle>
        <!-- Optional Parameters -->
        <mappingType>1</mappingType>
        <maxCmd>1.0</maxCmd>
        <maxForceFwd>250.0</maxForceFwd>
        <maxForceRev>-100.0</maxForceRev>
        <maxAngle>1.57079632679</maxAngle>
      </thruster>
    </plugin>
  </gazebo>
</robot>
