<sdf version='1.6'>
  <model name='aidboat'>
    <link name='base_link'>
      <pose frame=''>0 0 0 0 -0 0</pose>
      <inertial>
        <pose frame=''>-0.005665 0.261754 0.02036 0 -0 0</pose>
        <mass>32.964</mass>
        <inertia>
          <ixx>4.73597</ixx>
          <ixy>-0.0488778</ixy>
          <ixz>-0.00678956</ixz>
          <iyy>12.714</iyy>
          <iyz>-0.00241684</iyz>
          <izz>15.4312</izz>
        </inertia>
      </inertial>
      <collision name='base_link_fixed_joint_lump__top_base_collision'>
        <pose frame=''>0 0 0.1255 0 -0 0</pose>
        <geometry>
          <box>
            <size>0.73 1.15767 0.251</size>
          </box>
        </geometry>
      </collision>
      <collision name='base_link_fixed_joint_lump__right_hull_collision_1'>
        <pose frame=''>0.273998 0.447 -0.146 0 0 -0.024435</pose>
        <geometry>
          <box>
            <size>2.002 0.286 0.292</size>
          </box>
        </geometry>
      </collision>
      <collision name='base_link_fixed_joint_lump__left_hull_collision_2'>
        <pose frame=''>0.273998 -0.447 -0.146 0 -0 0.024435</pose>
        <geometry>
          <box>
            <size>2.002 0.286 0.292</size>
          </box>
        </geometry>
      </collision>
      <collision name='base_link_fixed_joint_lump__left_engine_link_collision_3'>
        <pose frame=''>-0.73 0.47 -0.016 3.14159 1.57079 3.11716</pose>
        <geometry>
          <cylinder>
            <length>0.113</length>
            <radius>0.05</radius>
          </cylinder>
        </geometry>
      </collision>
      <collision name='base_link_fixed_joint_lump__right_engine_link_collision_4'>
        <pose frame=''>-0.73 -0.47 -0.016 -3.14159 1.57079 -3.11716</pose>
        <geometry>
          <cylinder>
            <length>0.113</length>
            <radius>0.05</radius>
          </cylinder>
        </geometry>
      </collision>
      <visual name='base_link_fixed_joint_lump__dummy_link_visual'>
        <pose frame=''>0 0 0.292 0 -0 0</pose>
        <geometry>
          <mesh>
            <scale>1 1 1</scale>
            <uri>model://aidboat_description/meshes/AIDBOAT_Base.dae</uri>
          </mesh>
        </geometry>
      </visual>
      <visual name='base_link_fixed_joint_lump__left_engine_link_visual_1'>
        <pose frame=''>-0.741 0.47 -0.016 0 0 -0.024435</pose>
        <geometry>
          <mesh>
            <scale>1 1 1</scale>
            <uri>model://aidboat_description/meshes/left_engine.dae</uri>
          </mesh>
        </geometry>
      </visual>
      <visual name='base_link_fixed_joint_lump__right_engine_link_visual_2'>
        <pose frame=''>-0.741 -0.47 -0.016 0 -0 0.024435</pose>
        <geometry>
          <mesh>
            <scale>1 1 1</scale>
            <uri>model://aidboat_description/meshes/right_engine.dae</uri>
          </mesh>
        </geometry>
      </visual>
    </link>
    <link name='left_propeller_link'>
      <pose frame=''>-0.741 0.47 -0.016 0 -0 0</pose>
      <inertial>
        <pose frame=''>0 0 0 0 -0 0</pose>
        <mass>0.03</mass>
        <inertia>
          <ixx>5.8378e-07</ixx>
          <ixy>0</ixy>
          <ixz>0</ixz>
          <iyy>5.8378e-07</iyy>
          <iyz>0</iyz>
          <izz>2.17741e-05</izz>
        </inertia>
      </inertial>
      <collision name='left_propeller_link_collision'>
        <pose frame=''>0.011 0 0 3.14159 1.57079 3.11716</pose>
        <geometry>
          <cylinder>
            <length>0.03</length>
            <radius>0.0381</radius>
          </cylinder>
        </geometry>
      </collision>
      <visual name='left_propeller_link_visual'>
        <pose frame=''>0 0 0 0 0 -0.024435</pose>
        <geometry>
          <mesh>
            <scale>1 1 1</scale>
            <uri>model://aidboat_description/meshes/left_propeller.dae</uri>
          </mesh>
        </geometry>
      </visual>
    </link>
    <joint name='left_engine_propeller_joint' type='revolute'>
      <child>left_propeller_link</child>
      <parent>base_link</parent>
      <axis>
        <xyz>1 0 0</xyz>
        <limit>
          <lower>-1e+16</lower>
          <upper>1e+16</upper>
        </limit>
        <dynamics>
          <damping>0.05</damping>
          <friction>0.05</friction>
          <spring_reference>0</spring_reference>
          <spring_stiffness>0</spring_stiffness>
        </dynamics>
        <use_parent_model_frame>1</use_parent_model_frame>
      </axis>
    </joint>
    <link name='right_propeller_link'>
      <pose frame=''>-0.741 -0.47 -0.016 0 -0 0</pose>
      <inertial>
        <pose frame=''>0 0 0 0 -0 0</pose>
        <mass>0.03</mass>
        <inertia>
          <ixx>5.8378e-07</ixx>
          <ixy>0</ixy>
          <ixz>0</ixz>
          <iyy>5.8378e-07</iyy>
          <iyz>0</iyz>
          <izz>2.17741e-05</izz>
        </inertia>
      </inertial>
      <collision name='right_propeller_link_collision'>
        <pose frame=''>0.011 0 0 -3.14159 1.57079 -3.11716</pose>
        <geometry>
          <cylinder>
            <length>0.03</length>
            <radius>0.0381</radius>
          </cylinder>
        </geometry>
      </collision>
      <visual name='right_propeller_link_visual'>
        <pose frame=''>0 0 0 0 -0 0.024435</pose>
        <geometry>
          <mesh>
            <scale>1 1 1</scale>
            <uri>model://aidboat_description/meshes/right_propeller.dae</uri>
          </mesh>
        </geometry>
      </visual>
    </link>
    <joint name='right_engine_propeller_joint' type='revolute'>
      <child>right_propeller_link</child>
      <parent>base_link</parent>
      <axis>
        <xyz>1 0 0</xyz>
        <limit>
          <lower>-1e+16</lower>
          <upper>1e+16</upper>
        </limit>
        <dynamics>
          <damping>0.05</damping>
          <friction>0.05</friction>
          <spring_reference>0</spring_reference>
          <spring_stiffness>0</spring_stiffness>
        </dynamics>
        <use_parent_model_frame>1</use_parent_model_frame>
      </axis>
    </joint>
    <plugin name='aidboat_gazebo_thrust' filename='libusv_gazebo_thrust_plugin.so'>
      <cmdTimeout>1.0</cmdTimeout>
      <thruster>
        <linkName>left_engine_link</linkName>
        <propJointName>left_engine_propeller_joint</propJointName>
        <engineJointName>left_chasis_engine_joint</engineJointName>
        <cmdTopic>left_thrust_cmd</cmdTopic>
        <angleTopic>left_thrust_angle</angleTopic>
        <enableAngle>0</enableAngle>
      </thruster>
      <thruster>
        <linkName>right_engine_link</linkName>
        <propJointName>right_engine_propeller_joint</propJointName>
        <engineJointName>right_chasis_engine_joint</engineJointName>
        <cmdTopic>right_thrust_cmd</cmdTopic>
        <angleTopic>right_thrust_angle</angleTopic>
        <enableAngle>0</enableAngle>
      </thruster>
    </plugin>
    <static>0</static>
    <plugin name='usv_dynamics_aidboat' filename='libusv_gazebo_dynamics_plugin.so'>
      <bodyName>base_link</bodyName>
      <waterLevel>0</waterLevel>
      <waterDensity>997.8</waterDensity>
      <xDotU>0.0</xDotU>
      <yDotV>0.0</yDotV>
      <nDotR>0.0</nDotR>
      <xU>51.3</xU>
      <xUU>72.4</xUU>
      <yV>40.0</yV>
      <yVV>0.0</yVV>
      <zW>500.0</zW>
      <kP>50.0</kP>
      <mQ>50.0</mQ>
      <nR>400.0</nR>
      <nRR>0.0</nRR>
      <hullRadius>0.213</hullRadius>
      <boatWidth>1.15767</boatWidth>
      <boatLength>2.05992</boatLength>
      <length_n>2</length_n>
      <wave_model>ocean_waves</wave_model>
    </plugin>
  </model>
</sdf>
