<?xml version="1.0" encoding="utf-8"?>
<!-- =================================================================================== -->
<!-- |    This document was autogenerated by xacro from aidboat_gazebo.urdf.xacro      | -->
<!-- |    EDITING THIS FILE BY HAND IS NOT RECOMMENDED                                 | -->
<!-- =================================================================================== -->
<robot name="aidboat">
  <link name="base_link">
	</link>
  <joint name="dummy_joint" type="fixed">
    <origin rpy="0 0 0" xyz="0 0 0"/>
    <parent link="base_link"/>
    <child link="dummy_link"/>
  </joint>
  <link name="dummy_link">
    <inertial>
      <mass value="32.712"/>
      <origin rpy="0 0 0" xyz="0 0.26377 0.02064"/>
      <inertia ixx="4.662514672" ixy="0" ixz="0" iyy="12.57628507" iyz="0" izz="15.22053986"/>
    </inertial>
    <collision name="top_base">
      <origin rpy="0 0 0" xyz="0 0 0.1255"/>
      <geometry>
        <box size="0.73 1.15767 0.251"/>
      </geometry>
    </collision>
    <collision name="right_hull">
      <origin rpy="0 0 -0.0244346" xyz="0.273998 0.447 -0.146"/>
      <geometry>
        <box size="1.94 0.286 0.292"/>
      </geometry>
    </collision>
    <collision name="left_hull">
      <origin rpy="0 0 0.0244346" xyz="0.273998 -0.447 -0.146"/>
      <geometry>
        <box size="1.94 0.286 0.292"/>
      </geometry>
    </collision>
    <visual>
      <origin rpy="0 0 0" xyz="0 0 0.292"/>
      <geometry>
        <mesh filename="package://aidboat_description/meshes/base/AIDBOAT_Base.dae"/>
      </geometry>
    </visual>
  </link>
  <link name="right_engine_link">
    <visual>
      <origin rpy="0 0 0.0244346" xyz="0 0 0"/>
      <geometry>
        <mesh filename="package://aidboat_description/meshes/thrusters/engine.dae"/>
      </geometry>
    </visual>
    <collision>
      <origin rpy="0 1.5708 0.0244346" xyz="0.011 0 0"/>
      <geometry>
        <cylinder length="0.113" radius="0.05"/>
      </geometry>
    </collision>
    <inertial>
      <mass value="0.2752"/>
      <inertia ixx="0.00046483573" ixy="0.0" ixz="0.0" iyy="0.00046483573" iyz="0.0" izz="0.000344"/>
    </inertial>
  </link>
  <link name="right_propeller_link">
    <visual>
      <origin rpy="0 0 0.0244346" xyz="0 0 0"/>
      <geometry>
        <mesh filename="package://aidboat_description/meshes/thrusters/propeller.dae"/>
      </geometry>
    </visual>
    <collision>
      <origin rpy="0 1.5708 0.0244346" xyz="0.011 0 0"/>
      <geometry>
        <cylinder length="0.03" radius="0.0381"/>
      </geometry>
    </collision>
    <inertial>
      <mass value="0.0688"/>
      <inertia ixx="0.00003012769" ixy="0.0" ixz="0.0" iyy="0.00003012769" iyz="0.0" izz="0.00004993538"/>
    </inertial>
  </link>
  <joint name="right_chasis_engine_joint" type="revolute">
    <axis xyz="0 0 1"/>
    <limit effort="0" lower="0" upper="0" velocity="0"/>
    <origin rpy="0 0 0" xyz="-0.741 -0.47 -0.016"/>
    <parent link="base_link"/>
    <child link="right_engine_link"/>
  </joint>
  <joint name="right_engine_propeller_joint" type="continuous">
    <axis rpy="0 0 0" xyz="1 0 0"/>
    <parent link="right_engine_link"/>
    <child link="right_propeller_link"/>
    <origin rpy="0 0 0" xyz="0 0 0"/>
    <limit effort="100" velocity="100"/>
    <dynamics damping="0.05" friction="0.05"/>
  </joint>
  <link name="left_engine_link">
    <visual>
      <origin rpy="0 0 -0.0244346" xyz="0 0 0"/>
      <geometry>
        <mesh filename="package://aidboat_description/meshes/thrusters/engine.dae"/>
      </geometry>
    </visual>
    <collision>
      <origin rpy="0 1.5708 -0.0244346" xyz="0.011 0 0"/>
      <geometry>
        <cylinder length="0.113" radius="0.05"/>
      </geometry>
    </collision>
    <inertial>
      <mass value="0.2752"/>
      <inertia ixx="0.00046483573" ixy="0.0" ixz="0.0" iyy="0.00046483573" iyz="0.0" izz="0.000344"/>
    </inertial>
  </link>
  <link name="left_propeller_link">
    <visual>
      <origin rpy="0 0 -0.0244346" xyz="0 0 0"/>
      <geometry>
        <mesh filename="package://aidboat_description/meshes/thrusters/propeller.dae"/>
      </geometry>
    </visual>
    <collision>
      <origin rpy="0 1.5708 -0.0244346" xyz="0.011 0 0"/>
      <geometry>
        <cylinder length="0.03" radius="0.0381"/>
      </geometry>
    </collision>
    <inertial>
      <mass value="0.0688"/>
      <inertia ixx="0.00003012769" ixy="0.0" ixz="0.0" iyy="0.00003012769" iyz="0.0" izz="0.00004993538"/>
    </inertial>
  </link>
  <joint name="left_chasis_engine_joint" type="revolute">
    <axis xyz="0 0 1"/>
    <limit effort="0" lower="0" upper="0" velocity="0"/>
    <origin rpy="0 0 0" xyz="-0.741 0.47 -0.016"/>
    <parent link="base_link"/>
    <child link="left_engine_link"/>
  </joint>
  <joint name="left_engine_propeller_joint" type="continuous">
    <axis rpy="0 0 0" xyz="1 0 0"/>
    <parent link="left_engine_link"/>
    <child link="left_propeller_link"/>
    <origin rpy="0 0 0" xyz="0 0 0"/>
    <limit effort="100" velocity="100"/>
    <dynamics damping="0.05" friction="0.05"/>
  </joint>
  <gazebo>
    <plugin filename="libusv_gazebo_thrust_plugin.so" name="aidboat_gazebo_thrust">
      <cmdTimeout>1.0</cmdTimeout>
      <thruster>
        <linkName>right_propeller_link</linkName>
        <propJointName>right_engine_propeller_joint</propJointName>
        <engineJointName>right_chasis_engine_joint</engineJointName>
        <cmdTopic>right_thrust_cmd</cmdTopic>
        <angleTopic>right_thrust_angle</angleTopic>
        <enableAngle>false</enableAngle>
        <mappingType>0</mappingType>
        <maxCmd>1.0</maxCmd>
        <maxForceFwd>51.4849</maxForceFwd>
        <maxForceRev>-40.2073</maxForceRev>
      </thruster>
    </plugin>
    <plugin filename="libusv_gazebo_thrust_plugin.so" name="aidboat_gazebo_thrust">
      <cmdTimeout>1.0</cmdTimeout>
      <thruster>
        <linkName>left_propeller_link</linkName>
        <propJointName>left_engine_propeller_joint</propJointName>
        <engineJointName>left_chasis_engine_joint</engineJointName>
        <cmdTopic>left_thrust_cmd</cmdTopic>
        <angleTopic>left_thrust_angle</angleTopic>
        <enableAngle>false</enableAngle>
        <mappingType>0</mappingType>
        <maxCmd>1.0</maxCmd>
        <maxForceFwd>51.4849</maxForceFwd>
        <maxForceRev>-40.2073</maxForceRev>
      </thruster>
    </plugin>
  </gazebo>
  <!-- Gazebo Plugin for simulating boat dynamics -->
  <gazebo>
    <plugin filename="libusv_gazebo_dynamics_plugin.so" name="usv_dynamics_aidboat">
      <bodyName>base_link</bodyName>
      <!-- Must be same as the oxean model! -->
      <waterLevel>0</waterLevel>
      <waterDensity>997.8</waterDensity>
      <!-- Added mass -->
      <xDotU>0.0</xDotU>
      <yDotV>0.0</yDotV>
      <nDotR>0.0</nDotR>
      <!-- Linear and quadratic drag -->
      <xU>51.3</xU>
      <xUU>72.4</xUU>
      <yV>40.0</yV>
      <yVV>0.0</yVV>
      <zW>500.0</zW>
      <kP>50.0</kP>
      <mQ>50.0</mQ>
      <nR>400.0</nR>
      <nRR>0.0</nRR>
      <!-- General dimensions -->
      <!-- <boatArea>2.2</boatArea> -->
      <hullRadius>0.213</hullRadius>
      <boatWidth>1.15767</boatWidth>
      <boatLength>2.05992</boatLength>
      <!-- Length discretazion, AKA, "N" -->
      <length_n>2</length_n>
      <!-- Wave model -->
      <wave_model>ocean_waves</wave_model>
    </plugin>
  </gazebo>
  <link name="camera_link">
    <visual name="camera_visual">
      <origin rpy="1.5708 0 1.5708" xyz="0 -0.0147 -0.007"/>
      <geometry>
        <mesh filename="package://aidboat_gazebo/meshes/camera.dae"/>
      </geometry>
    </visual>
    <collision name="camera_collision">
      <origin rpy="0 0 0" xyz="0.014 -0.0147 -0.007"/>
      <geometry>
        <box size="0.028 0.0577 0.0403"/>
      </geometry>
    </collision>
    <inertial>
      <mass value="0.116"/>
      <inertia ixx="0.00004788267" ixy="0.0" ixz="0.0" iyy="0.0000397618" iyz="0.0" izz="0.0000232782"/>
    </inertial>
  </link>
  <joint name="camera_joint" type="fixed">
    <origin rpy="0 0 0" xyz="0.355 0 0.422"/>
    <parent link="base_link"/>
    <child link="camera_link"/>
  </joint>
  <link name="camera_link_optical">
        </link>
  <joint name="camera_to_camera_optical_joint" type="fixed">
    <origin rpy="-1.57079632679 0 -1.57079632679" xyz="0 0 0"/>
    <parent link="camera_link"/>
    <child link="camera_link_optical"/>
  </joint>
  <gazebo reference="camera_link">
    <mu1>0.2</mu1>
    <mu2>0.2</mu2>
  </gazebo>
  <gazebo reference="camera_link">
    <sensor name="camera_sensor" type="camera">
      <update_rate>30.0</update_rate>
      <camera name="camera_camera">
        <horizontal_fov>1.3962634</horizontal_fov>
        <image>
          <width>1280</width>
          <height>720</height>
          <format>R8G8B8</format>
        </image>
        <clip>
          <near>0.05</near>
          <far>300</far>
        </clip>
        <noise>
          <type>gaussian</type>
          <!-- Noise is sampled independently per pixel on each frame. That pixel's noise value is added to ach of its color channels, which at that point lie in the range [0,1]. -->
          <mean>0.0</mean>
          <stddev>0.007</stddev>
        </noise>
      </camera>
      <plugin filename="libgazebo_ros_camera.so" name="aidboat_camera_plugin">
        <alwaysOn>true</alwaysOn>
        <updateRate>0.0</updateRate>
        <cameraName>aidboat/sensors/camera</cameraName>
        <imageTopicName>image_raw</imageTopicName>
        <cameraInfoTopicName>camera_info</cameraInfoTopicName>
        <frameName>camera_link_optical</frameName>
        <hackBaseline>0.07</hackBaseline>
        <distorsionK1>0.0</distorsionK1>
        <distortionK2>0.0</distortionK2>
        <distortionK3>0.0</distortionK3>
        <distortionT1>0.0</distortionT1>
        <distortionT2>0.0</distortionT2>
      </plugin>
    </sensor>
  </gazebo>
  <link name="gps_link">
    <visual name="gps_visual">
      <geometry>
        <cylinder length="0.081" radius="0.0775"/>
      </geometry>
      <material name="White">
        <color rgba="1.0 1.0 1.0 1.0"/>
      </material>
    </visual>
    <collision name="gps_collision">
      <geometry>
        <cylinder length="0.081" radius="0.0775"/>
      </geometry>
    </collision>
    <inertial>
      <mass value="0.470"/>
      <inertia ixx="0.00096270687" ixy="0.0" ixz="0.0" iyy="0.00096270687" iyz="0.0" izz="0.00141146875"/>
    </inertial>
  </link>
  <joint name="gps_joint" type="fixed">
    <origin rpy="0 0 0" xyz="0.23 0.45 0.3736"/>
    <parent link="base_link"/>
    <child link="gps_link"/>
  </joint>
  <gazebo reference="gps_link">
    <material>Gazebo/White</material>
  </gazebo>
  <gazebo>
    <plugin filename="libhector_gazebo_ros_gps.so" name="aidboat_gps_plugin">
      <alwaysOn>true</alwaysOn>
      <updateRate>15</updateRate>
      <bodyName>gps_link</bodyName>
      <frameId>aidboat/gps_link</frameId>
      <topicName>aidboat/sensors/gps/fix</topicName>
      <velocityTopicName>aidboat/sensors/gps/fix_velocity</velocityTopicName>
      <referenceLatitude>21.30996</referenceLatitude>
      <referenceLongitude>-157.8901</referenceLongitude>
      <referenceAltitude>0</referenceAltitude>
      <referenceHeading>90</referenceHeading>
      <offset>0 0 0</offset>
      <drift>0 0 0</drift>
      <gaussianNoise>0 0 0</gaussianNoise>
      <velocityOffset>0 0 0</velocityOffset>
      <velocityDrift>0 0 0</velocityDrift>
      <velocityGaussianNoise>0 0 0</velocityGaussianNoise>
    </plugin>
  </gazebo>
  <link name="imu_link">
    <visual name="imu_visual">
      <geometry>
        <box size="0.024 0.044 0.011"/>
      </geometry>
      <material name="White">
        <color rgba="1.0 1.0 1.0 1.0"/>
      </material>
    </visual>
    <collision name="imu_collision">
      <geometry>
        <box size="0.044 0.024 0.011"/>
      </geometry>
    </collision>
    <inertial>
      <mass value="0.018"/>
      <inertia ixx="0.0000010455" ixy="0" ixz="0" iyy="0.000003768" iyz="0" izz="0.0000030855"/>
    </inertial>
  </link>
  <joint name="imu_joint" type="fixed">
    <origin rpy="0 0 0" xyz="-0.28 0 0.3386"/>
    <parent link="base_link"/>
    <child link="imu_link"/>
  </joint>
  <gazebo reference="imu_link">
    <material>Gazebo/White</material>
  </gazebo>
  <gazebo>
    <plugin filename="libhector_gazebo_ros_imu.so" name="aidboat_imu_plugin">
      <updateRate>50</updateRate>
      <bodyName>imu_link</bodyName>
      <topicName>aidboat/sensors/imu/data</topicName>
      <serviceName>aidboat/sensors/imu_service</serviceName>
      <!--Manually prepend namespace to tf frame -->
      <frameId>aidboat/imu_link</frameId>
      <alwaysOn>true</alwaysOn>
      <accelOffset>0.0 0.0 0.0</accelOffset>
      <accelDrift>0.005 0.005 0.005</accelDrift>
      <accelDriftFrequency>0.00027 0.00027 0.000027</accelDriftFrequency>
      <accelGaussianNoise>0.005 0.005 0.005</accelGaussianNoise>
      <rateOffset>0.0 0.0 0.0</rateOffset>
      <rateDrift>0.005 0.005 0.005</rateDrift>
      <rateDriftFrequency>0.00027 0.00027 0.000027</rateDriftFrequency>
      <rateGaussianNoise>0.005 0.005 0.005</rateGaussianNoise>
      <yawOffset>0.0</yawOffset>
      <yawDrift>0.0</yawDrift>
      <yawDriftFrequency>0.00027</yawDriftFrequency>
      <yawGaussianNoise>0.0</yawGaussianNoise>
    </plugin>
  </gazebo>
  <link name="lidar_link">
    <visual name="lidar_visual">
      <origin rpy="0 0 -1.5708" xyz="0 0 0"/>
      <geometry>
        <mesh filename="package://aidboat_gazebo/meshes/lidar.stl"/>
        <!--<cylinder radius="0.0525" length="0.152"/>-->
      </geometry>
    </visual>
    <collision name="lidar_collision">
      <origin rpy="0 0 0" xyz="0.014 0 0"/>
      <geometry>
        <cylinder length="0.152" radius="0.0525"/>
      </geometry>
    </collision>
    <inertial>
      <mass value="1.1"/>
      <inertia ixx="0.00478826733" ixy="0.0" ixz="0.0" iyy="0.00414728033" iyz="0.0" izz="0.00249892033"/>
    </inertial>
  </link>
  <joint name="lidar_joint" type="fixed">
    <origin rpy="0 0 0" xyz="-0.28 0 0.543"/>
    <parent link="base_link"/>
    <child link="lidar_link"/>
  </joint>
  <link name="lidar_laser">
        </link>
  <joint name="lidar_laser_joint" type="fixed">
    <origin rpy="0 0 0" xyz="0.055 0 0.116"/>
    <parent link="lidar_link"/>
    <child link="lidar_laser"/>
  </joint>
  <material name="black">
    <color rgba="0 0 0 1.0"/>
  </material>
  <gazebo reference="lidar_laser">
    <sensor name="lidar_sensor" type="ray">
      <pose>0 0 0 0 0 0</pose>
      <visualize>False</visualize>
      <update_rate>15</update_rate>
      <ray>
        <scan>
          <horizontal>
            <samples>540</samples>
            <resolution>1</resolution>
            <min_angle>-2.357</min_angle>
            <max_angle>2.357</max_angle>
          </horizontal>
        </scan>
        <range>
          <min>0.5</min>
          <max>20.0</max>
          <resolution>0.01</resolution>
        </range>
        <noise>
          <type>gaussian</type>
          <mean>0.0</mean>
          <stddev>0.01</stddev>
        </noise>
      </ray>
      <plugin filename="libgazebo_ros_laser.so" name="aidboat_lidar_plugin">
        <topicName>/aidboat/sensors/laser/scan</topicName>
        <frameName>lidar_laser</frameName>
      </plugin>
    </sensor>
  </gazebo>
  <gazebo>
    <plugin filename="libgazebo_ros_p3d.so" name="aidboat_p3d_plugin">
      <bodyName>base_link</bodyName>
      <frameName>map</frameName>
      <updateRate>10.0</updateRate>
      <topicName>aidboat/sensors/position/ground_truth_odometry</topicName>
      <xyzOffset>0 0 0</xyzOffset>
      <rpyOffset>0 0 0</rpyOffset>
      <gaussianNoise>0</gaussianNoise>
    </plugin>
  </gazebo>
</robot>
